Workbook

Sheet BASE
A1: Episódios do NerdCast: | B1: Link | C1: Data | D1: Dia | E1: Mês | F1: Ano | G1: DT Data | H1: Data Semana | I1: Tipo + Episódio | J1: Tipo | K1: # Episódio | L1: Dif Data
A2: Título: NerdCast 01 - Super-Homem: Herói americano ou do mundo? - | B2: https://jovemnerd.com.br/nerdcast/01-super-homem-heroi-americando-ou-do-mundo/ | C2: Sun, 02 Apr 2006 17:39:39 +0000 | D2: 02 | E2: 4 | F2: 2006 | G2: 38809 | H2: 1 | I2: NerdCast 01 | J2: NerdCast | K2: 01
A3: Título: NerdCast 02 - Batman Continues: Quem serão os vilões? - | B3: https://jovemnerd.com.br/nerdcast/02-batman-continues-quem-serao-os-viloes/ | C3: Sun, 02 Apr 2006 17:43:22 +0000 | D3: 02 | E3: 4 | F3: 2006 | G3: 38809 | H3: 1 | I3: NerdCast 02 | J3: NerdCast | K3: 02 | L3: =G3-G2 -> 0
A4: Título: NerdCast 03 - Quadrinhos: A volta de Jason Todd (?!) - | B4: https://jovemnerd.com.br/nerdcast/03-quadrinhos-a-volta-de-jason-todd/ | C4: Sun, 02 Apr 2006 17:46:32 +0000 | D4: 02 | E4: 4 | F4: 2006 | G4: 38809 | H4: 1 | I4: NerdCast 03 | J4: NerdCast | K4: 03 | L4: =G4-G3 -> 0
A5: Título: NerdCast 04 - Rocky Balboa está de volta: comemorar ou chorar? - | B5: https://jovemnerd.com.br/nerdcast/04-rocky-balboa-esta-de-volta-comemorar-ou-chorar/ | C5: Sun, 02 Apr 2006 17:47:44 +0000 | D5: 02 | E5: 4 | F5: 2006 | G5: 38809 | H5: 1 | I5: NerdCast 04 | J5: NerdCast | K5: 04 | L5: =G5-G4 -> 0
A6: Título: NerdCast 05 - Bárbaros, Exterminadores e uma Vareta Espacial - | B6: https://jovemnerd.com.br/nerdcast/nerdcast-05-barbaros-exterminadores-e-uma-vareta-espacial/ | C6: Sun, 02 Apr 2006 19:19:01 +0000 | D6: 02 | E6: 4 | F6: 2006 | G6: 38809 | H6: 1 | I6: NerdCast 05 | J6: NerdCast | K6: 05 | L6: =G6-G5 -> 0
A7: Título: NerdCast 06 - V de Vingança - | B7: https://jovemnerd.com.br/nerdcast/nerdcast-06-v-de-vinganca/ | C7: Sat, 08 Apr 2006 17:11:14 +0000 | D7: 08 | E7: 4 | F7: 2006 | G7: 38815 | H7: 7 | I7: NerdCast 06 | J7: NerdCast | K7: 06 | L7: =G7-G6 -> 6
A8: Título: NerdCast 07 - Os brucutus dos anos 80 - | B8: https://jovemnerd.com.br/nerdcast/nerdcast-07-os-brucutus-dos-anos-80/ | C8: Tue, 11 Apr 2006 01:32:49 +0000 | D8: 11 | E8: 4 | F8: 2006 | G8: 38818 | H8: 3 | I8: NerdCast 07 | J8: NerdCast | K8: 07 | L8: =G8-G7 -> 3
A9: Título: NerdCast 08 - O Poderoso Chefão - | B9: https://jovemnerd.com.br/nerdcast/nerdcast-08-o-poderoso-chefao/ | C9: Tue, 18 Apr 2006 00:57:31 +0000 | D9: 18 | E9: 4 | F9: 2006 | G9: 38825 | H9: 3 | I9: NerdCast 08 | J9: NerdCast | K9: 08 | L9: =G9-G8 -> 7
A10: Título: NerdCast 09 - Pérolas do RPG - | B10: https://jovemnerd.com.br/nerdcast/nerdcast-09-perolas-do-rpg/ | C10: Fri, 21 Apr 2006 14:15:39 +0000 | D10: 21 | E10: 4 | F10: 2006 | G10: 38828 | H10: 6 | I10: NerdCast 09 | J10: NerdCast | K10: 09 | L10: =G10-G9 -> 3
A11: Título: NerdCast 10 - Nostalgia Tecnológica - | B11: https://jovemnerd.com.br/nerdcast/nerdcast-10-nostalgia-tecnologica/ | C11: Fri, 28 Apr 2006 03:24:55 +0000 | D11: 28 | E11: 4 | F11: 2006 | G11: 38835 | H11: 6 | I11: NerdCast 10 | J11: NerdCast | K11: 10 | L11: =G11-G10 -> 7
A12: Título: NerdCast 11 - Missão: Nerdcast - | B12: https://jovemnerd.com.br/nerdcast/nerdcast-11-missao-nerdcast/ | C12: Sun, 07 May 2006 23:44:26 +0000 | D12: 07 | E12: 5 | F12: 2006 | G12: 38844 | H12: 1 | I12: NerdCast 11 | J12: NerdCast | K12: 11 | L12: =G12-G11 -> 9
A13: Título: NerdCast 12 - Os primórdios dos vídeo games - | B13: https://jovemnerd.com.br/nerdcast/nerdcast-12-os-primordios-dos-video-games/ | C13: Thu, 11 May 2006 02:19:04 +0000 | D13: 11 | E13: 5 | F13: 2006 | G13: 38848 | H13: 5 | I13: NerdCast 12 | J13: NerdCast | K13: 12 | L13: =G13-G12 -> 4
A14: Título: NerdCast 13 - Google é meu pastor e nada me faltará - | B14: https://jovemnerd.com.br/nerdcast/nerdcast-13-google-e-meu-pastor-e-nada-me-faltara/ | C14: Wed, 17 May 2006 01:47:02 +0000 | D14: 17 | E14: 5 | F14: 2006 | G14: 38854 | H14: 4 | I14: NerdCast 13 | J14: NerdCast | K14: 13 | L14: =G14-G13 -> 6
... A520: Título: NerdCast 494 - Desista da Dieta - | B520: https://jovemnerd.com.br/nerdcast/nerdcast-494-desista-da-dieta/ | C520: Fri, 04 Dec 2015 02:37:43 +0000 | D520: 04 | E520: 12 | F520: 2015 | G520: 42342 | H520: 6 | I520: NerdCast 494 | J520: NerdCast | K520: 494 | L520: =G520-G519 -> 7
A521: Título: HaloCast Oferecido por Xbox - HaloCast 1 - | B521: https://jovemnerd.com.br/nerdcast/extra/halocast-1/ | C521: Fri, 11 Dec 2015 17:37:11 +0000 | D521: 11 | E521: 12 | F521: 2015 | G521: 42349 | H521: 6 | I521: HaloCast Oferecido por Xbox | J521: HaloCast Oferecido por Xbox | L521: =G521-G520 -> 7
A522: Título: NerdCast 495 - A Revolução Star Wars - | B522: https://jovemnerd.com.br/nerdcast/nerdcast-495-a-revolucao-star-wars/ | C522: Fri, 11 Dec 2015 11:30:23 +0000 | D522: 11 | E522: 12 | F522: 2015 | G522: 42349 | H522: 6 | I522: NerdCast 495 | J522: NerdCast | K522: 495 | L522: =G522-G521 -> 0
A523: Título: HaloCast Oferecido por Xbox - HaloCast 2 - | B523: https://jovemnerd.com.br/nerdcast/extra/halocast-2/ | C523: Thu, 17 Dec 2015 18:54:46 +0000 | D523: 17 | E523: 12 | F523: 2015 | G523: 42355 | H523: 5 | I523: HaloCast Oferecido por Xbox | J523: HaloCast Oferecido por Xbox | L523: =G523-G522 -> 6
A524: Título: Empreendedor 12 - A vida depois da venda - | B524: https://jovemnerd.com.br/nerdcast/empreendedor/nerdcast-empreendedor-12-a-vida-depois-da-venda/ | C524: Fri, 18 Dec 2015 09:07:47 +0000 | D524: 18 | E524: 12 | F524: 2015 | G524: 42356 | H524: 6 | I524: Empreendedor 12 | J524: Empreendedor | K524: 12 | L524: =G524-G523 -> 1
A525: Título: NerdCast 496 - Uma viajante no Oriente Médio - | B525: https://jovemnerd.com.br/nerdcast/nerdcast-496-uma-viajante-no-oriente-medio/ | C525: Fri, 18 Dec 2015 09:08:28 +0000 | D525: 18 | E525: 12 | F525: 2015 | G525: 42356 | H525: 6 | I525: NerdCast 496 | J525: NerdCast | K525: 496 | L525: =G525-G524 -> 0
A526: Título: HaloCast Oferecido por Xbox - HaloCast 3 - | B526: https://jovemnerd.com.br/nerdcast/extra/halocast-3/ | C526: Tue, 22 Dec 2015 13:33:04 +0000 | D526: 22 | E526: 12 | F526: 2015 | G526: 42360 | H526: 3 | I526: HaloCast Oferecido por Xbox | J526: HaloCast Oferecido por Xbox | L526: =G526-G525 -> 4
A527: Título: NerdCast 497 - Star Wars VII – O despertar das emoções - | B527: https://jovemnerd.com.br/nerdcast/nerdcast-497-star-wars-vii-o-despertar-das-emocoes/ | C527: Fri, 25 Dec 2015 00:01:59 +0000 | D527: 25 | E527: 12 | F527: 2015 | G527: 42363 | H527: 6 | I527: NerdCast 497 | J527: NerdCast | K527: 497 | L527: =G527-G526 -> 3
A528: Título: NerdCast RPG 498 - RPG Cyberpunk 3: Estrada para o inferno - | B528: https://jovemnerd.com.br/nerdcast/nerdcast-498-rpg-cyberpunk-3-estrada-para-o-inferno/ | C528: Fri, 08 Jan 2016 22:08:39 +0000 | D528: 08 | E528: 1 | F528: 2016 | G528: 42377 | H528: 6 | I528: NerdCast RPG 498 | J528: NerdCast RPG | K528: 498 | L528: =G528-G527 -> 14
A529: Título: NerdCast 499 - Bandas de Garagem - | B529: https://jovemnerd.com.br/nerdcast/nerdcast-499-bandas-de-garagem/ | C529: Fri, 15 Jan 2016 07:04:47 +0000 | D529: 15 | E529: 1 | F529: 2016 | G529: 42384 | H529: 6 | I529: NerdCast 499 | J529: NerdCast | K529: 499 | L529: =G529-G528 -> 7
A530: Título: NerdCast 500 - O Melhor de 500 Nerdcasts! - | B530: https://jovemnerd.com.br/nerdcast/nerdcast-500-o-melhor-de-500-nerdcasts/ | C530: Fri, 22 Jan 2016 12:57:06 +0000 | D530: 22 | E530: 1 | F530: 2016 | G530: 42391 | H530: 6 | I530: NerdCast 500 | J530: NerdCast | K530: 500 | L530: =G530-G529 -> 7
A531: Título: Empreendedor 13 - Empreendedorismo Digital - | B531: https://jovemnerd.com.br/nerdcast/empreendedor/nerdcast-empreendedor-13-empreendedorismo-digital/ | C531: Fri, 29 Jan 2016 09:30:50 +0000 | D531: 29 | E531: 1 | F531: 2016 | G531: 42398 | H531: 6 | I531: Empreendedor 13 | J531: Empreendedor | K531: 13 | L531: =G531-G530 -> 7
A532: Título: NerdCast 501 - Pega na mentira! - | B532: https://jovemnerd.com.br/nerdcast/nerdcast-501-pega-na-mentira/ | C532: Fri, 29 Jan 2016 09:31:12 +0000 | D532: 29 | E532: 1 | F532: 2016 | G532: 42398 | H532: 6 | I532: NerdCast 501 | J532: NerdCast | K532: 501 | L532: =G532-G531 -> 0
A533: Título: NerdCast 502 - A moderna monarquia britânica - | B533: https://jovemnerd.com.br/nerdcast/nerdcast-502-a-moderna-monarquia-britanica/ | C533: Fri, 05 Feb 2016 00:38:20 +0000 | D533: 05 | E533: 2 | F533: 2016 | G533: 42405 | H533: 6 | I533: NerdCast 502 | J533: NerdCast | K533: 502 | L533: =G533-G532 -> 7
A534: Título: NerdCast 503 - Esse Zika é vírus! - | B534: https://jovemnerd.com.br/nerdcast/nerdcast-503-esse-zika-e-virus/ | C534: Thu, 11 Feb 2016 23:01:12 +0000 | D534: 11 | E534: 2 | F534: 2016 | G534: 42411 | H534: 5 | I534: NerdCast 503 | J534: NerdCast | K534: 503 | L534: =G534-G533 -> 6
A535: Título: NerdCast 504 - Comfort Food - | B535: https://jovemnerd.com.br/nerdcast/nerdcast-504-comfort-food/ | C535: Thu, 18 Feb 2016 23:06:12 +0000 | D535: 18 | E535: 2 | F535: 2016 | G535: 42418 | H535: 5 | I535: NerdCast 504 | J535: NerdCast | K535: 504 | L535: =G535-G534 -> 7
A536: Título: Empreendedor 14 - Empreendendo entre gigantes - | B536: https://jovemnerd.com.br/nerdcast/empreendedor/nerdcast-empreendedor-14-empreendendo-entre-gigantes/ | C536: Fri, 26 Feb 2016 09:44:04 +0000 | D536: 26 | E536: 2 | F536: 2016 | G536: 42426 | H536: 6 | I536: Empreendedor 14 | J536: Empreendedor | K536: 14 | L536: =G536-G535 -> 8
A537: Título: NerdCast 505 - Doctor… Who? - | B537: https://jovemnerd.com.br/nerdcast/nerdcast-505-doctor-who/ | C537: Fri, 26 Feb 2016 09:44:44 +0000 | D537: 26 | E537: 2 | F537: 2016 | G537: 42426 | H537: 6 | I537: NerdCast 505 | J537: NerdCast | K537: 505 | L537: =G537-G536 -> 0
A538: Título: NerdCast 506 - Cegos, nerds e loucos 2 - | B538: https://jovemnerd.com.br/nerdcast/nerdcast-506-cegos-nerds-e-loucos-2/ | C538: Fri, 04 Mar 2016 10:22:04 +0000 | D538: 04 | E538: 3 | F538: 2016 | G538: 42433 | H538: 6 | I538: NerdCast 506 | J538: NerdCast | K538: 506 | L538: =G538-G537 -> 7
... A636: Título: NerdCast 572 - A origem da vida - | B636: https://jovemnerd.com.br/nerdcast/origem-da-vida/ | C636: Fri, 16 Jun 2017 11:00:27 +0000 | D636: 16 | E636: 6 | F636: 2017 | G636: 42902 | H636: 6 | I636: NerdCast 572 | J636: NerdCast | K636: 572 | L636: =G636-G635 -> 7
A637: Título: Extra Oferecido por GE - Indústrias Superpoderosas - | B637: https://jovemnerd.com.br/nerdcast/extra/nerdcast-ge-industrias-superpoderosas/ | C637: Fri, 23 Jun 2017 11:00:07 +0000 | D637: 23 | E637: 6 | F637: 2017 | G637: 42909 | H637: 6 | I637: Extra Oferecido por GE | J637: Extra Oferecido por GE | L637: =G637-G636 -> 7
A638: Título: NerdCast 573 - Momentos Sublimes - | B638: https://jovemnerd.com.br/nerdcast/momentos-sublimes/ | C638: Fri, 23 Jun 2017 11:01:35 +0000 | D638: 23 | E638: 6 | F638: 2017 | G638: 42909 | H638: 6 | I638: NerdCast 573 | J638: NerdCast | K638: 573 | L638: =G638-G637 -> 0
A639: Título: Empreendedor 30 - Visão, coragem e competência - | B639: https://jovemnerd.com.br/nerdcast/empreendedor/visao-coragem-e-competencia/ | C639: Fri, 30 Jun 2017 11:00:14 +0000 | D639: 30 | E639: 6 | F639: 2017 | G639: 42916 | H639: 6 | I639: Empreendedor 30 | J639: Empreendedor | K639: 30 | L639: =G639-G638 -> 7
A640: Título: NerdCast 574 - A Reforma Protestante - | B640: https://jovemnerd.com.br/nerdcast/a-reforma-protestante/ | C640: Fri, 30 Jun 2017 11:01:37 +0000 | D640: 30 | E640: 6 | F640: 2017 | G640: 42916 | H640: 6 | I640: NerdCast 574 | J640: NerdCast | K640: 574 | L640: =G640-G639 -> 0
A641: Título: NerdCast 575 - Nossa língua portuguesa - | B641: https://jovemnerd.com.br/nerdcast/nossa-lingua-portuguesa/ | C641: Fri, 07 Jul 2017 11:01:00 +0000 | D641: 07 | E641: 7 | F641: 2017 | G641: 42923 | H641: 6 | I641: NerdCast 575 | J641: NerdCast | K641: 575 | L641: =G641-G640 -> 7
A642: Título: NerdTech 17 - Aprendizado Online - | B642: https://jovemnerd.com.br/nerdcast/nerdtech/aprendizado-online/ | C642: Fri, 07 Jul 2017 11:00:15 +0000 | D642: 07 | E642: 7 | F642: 2017 | G642: 42923 | H642: 6 | I642: NerdTech 17 | J642: NerdTech | K642: 17 | L642: =G642-G641 -> 0
...

Sheet NerdCasts
A1: Episódios do NerdCast: | B1: Link | C1: Data | D1: Dia | E1: Mês | F1: Ano | G1: DT Data | H1: Data Semana | I1: Tipo + Episódio | J1: Tipo | K1: # Episódio | L1: Dif Data
A2: Título: NerdCast 01 - Super-Homem: Herói americano ou do mundo? - | B2: =VLOOKUP(A2,BASE!$A:$B,2,FALSE) -> https://jovemnerd.com.br/nerdcast/01-super-homem-heroi-americando-ou-do-mundo/ | C2: Sun, 02 Apr 2006 17:39:39 +0000 | D2: 02 | E2: 4 | F2: 2006 | G2: 38809 | H2: 1 | I2: NerdCast 01 | J2: NerdCast | K2: 01 | L2: 0
A3: Título: NerdCast 02 - Batman Continues: Quem serão os vilões? - | B3: =VLOOKUP(A3,BASE!$A:$B,2,FALSE) -> https://jovemnerd.com.br/nerdcast/02-batman-continues-quem-serao-os-viloes/ | C3: Sun, 02 Apr 2006 17:43:22 +0000 | D3: 02 | E3: 4 | F3: 2006 | G3: 38809 | H3: 1 | I3: NerdCast 02 | J3: NerdCast | K3: 02 | L3: =G3-G2 -> 0
A4: Título: NerdCast 03 - Quadrinhos: A volta de Jason Todd (?!) - | B4: =VLOOKUP(A4,BASE!$A:$B,2,FALSE) -> https://jovemnerd.com.br/nerdcast/03-quadrinhos-a-volta-de-jason-todd/ | C4: Sun, 02 Apr 2006 17:46:32 +0000 | D4: 02 | E4: 4 | F4: 2006 | G4: 38809 | H4: 1 | I4: NerdCast 03 | J4: NerdCast | K4: 03 | L4: =G4-G3 -> 0
A5: Título: NerdCast 04 - Rocky Balboa está de volta: comemorar ou chorar? - | B5: =VLOOKUP(A5,BASE!$A:$B,2,FALSE) -> https://jovemnerd.com.br/nerdcast/04-rocky-balboa-esta-de-volta-comemorar-ou-chorar/ | C5: Sun, 02 Apr 2006 17:47:44 +0000 | D5: 02 | E5: 4 | F5: 2006 | G5: 38809 | H5: 1 | I5: NerdCast 04 | J5: NerdCast | K5: 04 | L5: =G5-G4 -> 0
A6: Título: NerdCast 05 - Bárbaros, Exterminadores e uma Vareta Espacial - | B6: =VLOOKUP(A6,BASE!$A:$B,2,FALSE) -> https://jovemnerd.com.br/nerdcast/nerdcast-05-barbaros-exterminadores-e-uma-vareta-espacial/ | C6: Sun, 02 Apr 2006 19:19:01 +0000 | D6: 02 | E6: 4 | F6: 2006 | G6: 38809 | H6: 1 | I6: NerdCast 05 | J6: NerdCast | K6: 05 | L6: =G6-G5 -> 0
A7: Título: NerdCast 06 - V de Vingança - | B7: =VLOOKUP(A7,BASE!$A:$B,2,FALSE) -> https://jovemnerd.com.br/nerdcast/nerdcast-06-v-de-vinganca/ | C7: Sat, 08 Apr 2006 17:11:14 +0000 | D7: 08 | E7: 4 | F7: 2006 | G7: 38815 | H7: 7 | I7: NerdCast 06 | J7: NerdCast | K7: 06 | L7: =G7-G6 -> 6
A8: Título: NerdCast 07 - Os brucutus dos anos 80 - | B8: =VLOOKUP(A8,BASE!$A:$B,2,FALSE) -> https://jovemnerd.com.br/nerdcast/nerdcast-07-os-brucutus-dos-anos-80/ | C8: Tue, 11 Apr 2006 01:32:49 +0000 | D8: 11 | E8: 4 | F8: 2006 | G8: 38818 | H8: 3 | I8: NerdCast 07 | J8: NerdCast | K8: 07 | L8: =G8-G7 -> 3
A9: Título: NerdCast 08 - O Poderoso Chefão - | B9: =VLOOKUP(A9,BASE!$A:$B,2,FALSE) -> https://jovemnerd.com.br/nerdcast/nerdcast-08-o-poderoso-chefao/ | C9: Tue, 18 Apr 2006 00:57:31 +0000 | D9: 18 | E9: 4 | F9: 2006 | G9: 38825 | H9: 3 | I9: NerdCast 08 | J9: NerdCast | K9: 08 | L9: =G9-G8 -> 7
A10: Título: NerdCast 09 - Pérolas do RPG - | B10: =VLOOKUP(A10,BASE!$A:$B,2,FALSE) -> https://jovemnerd.com.br/nerdcast/nerdcast-09-perolas-do-rpg/ | C10: Fri, 21 Apr 2006 14:15:39 +0000 | D10: 21 | E10: 4 | F10: 2006 | G10: 38828 | H10: 6 | I10: NerdCast 09 | J10: NerdCast | K10: 09 | L10: =G10-G9 -> 3
A11: Título: NerdCast 10 - Nostalgia Tecnológica - | B11: =VLOOKUP(A11,BASE!$A:$B,2,FALSE) -> https://jovemnerd.com.br/nerdcast/nerdcast-10-nostalgia-tecnologica/ | C11: Fri, 28 Apr 2006 03:24:55 +0000 | D11: 28 | E11: 4 | F11: 2006 | G11: 38835 | H11: 6 | I11: NerdCast 10 | J11: NerdCast | K11: 10 | L11: =G11-G10 -> 7
A12: Título: NerdCast 11 - Missão: Nerdcast - | B12: =VLOOKUP(A12,BASE!$A:$B,2,FALSE) -> https://jovemnerd.com.br/nerdcast/nerdcast-11-missao-nerdcast/ | C12: Sun, 07 May 2006 23:44:26 +0000 | D12: 07 | E12: 5 | F12: 2006 | G12: 38844 | H12: 1 | I12: NerdCast 11 | J12: NerdCast | K12: 11 | L12: =G12-G11 -> 9
A13: Título: NerdCast 12 - Os primórdios dos vídeo games - | B13: =VLOOKUP(A13,BASE!$A:$B,2,FALSE) -> https://jovemnerd.com.br/nerdcast/nerdcast-12-os-primordios-dos-video-games/ | C13: Thu, 11 May 2006 02:19:04 +0000 | D13: 11 | E13: 5 | F13: 2006 | G13: 38848 | H13: 5 | I13: NerdCast 12 | J13: NerdCast | K13: 12 | L13: =G13-G12 -> 4
A14: Título: NerdCast 13 - Google é meu pastor e nada me faltará - | B14: =VLOOKUP(A14,BASE!$A:$B,2,FALSE) -> https://jovemnerd.com.br/nerdcast/nerdcast-13-google-e-meu-pastor-e-nada-me-faltara/ | C14: Wed, 17 May 2006 01:47:02 +0000 | D14: 17 | E14: 5 | F14: 2006 | G14: 38854 | H14: 4 | I14: NerdCast 13 | J14: NerdCast | K14: 13 | L14: =G14-G13 -> 6
... A978: Título: NerdCast 963 - Qual é a pauta? Cabide de esteira, whey e Cindy Lauper - | B978: =VLOOKUP(A978,BASE!$A:$B,2,FALSE) -> https://jovemnerd.com.br/nerdcast/qual-e-a-pauta-cabide-de-esteira-whey-e-cindy-lauper/ | C978: Fri, 20 Dec 2024 12:19:49 +0000 | D978: 20 | E978: 12 | F978: 2024 | G978: 45646 | H978: 6 | I978: NerdCast 963 | J978: NerdCast | K978: 963 | L978: =G978-G977 -> 7
G979: =TODAY() -> 45852 | L979: =G979-G978 -> 206

Sheet Página10
A2: Chegamos ao Top 3 Maior período sem NerdCast
A4: Hoje (06/Jan) fazem 17 dias desde a última publicação de um NerdCast
A6: Fiquei na dúvida sobre quão raro é não ter nenhum NerdCast na semana
A8: Então eu levantei as datas de publicação do feed RSS para todos os Ep de NerdCast (que contam para a sequência de 963 ep*) cheguei aos seguintes números:
A10: Os dois maiores hiatos entre episódios foram de 21 dias, nos ep 193 e 292 - ambos publicados em Janeiro, após o recesso de fim de ano (2010 e 2012).
A11: O terceiro maior hiato foi de 17 dias, ep 113b - lá em 2008. Não sei se teve algum erro nessa publicação, pois está na mesma data do 114, e saíram em uma segunda-feira.
A12: Desde jan/2024 - ep 914 (Nerdcast RPG - 13d) e ep 915 (15d) - não havia hiatos. E antes disso o último foi em jan/2020 (ep 707) - também após recesso.
A13: Tirando o NC RPG Cyberpunk 3 e Ghanor 6, os ep de NC RPG não costumam "atrasar" (no sentido de ter um ep na sexta anterior), mas geralmente os ep após os NC RPG atrasam 1 a 2 semanas.
A14: Se considerar todo o histórico de NerdCasts (desde 2006), tem apenas 17 semanas em que a diferença entre publicações foi > 8 dias. Dá menos de 2% de atrasos.
A16: Os dados extraídos estão aqui caso alguém queira dar uma olhada: https://docs.google.com/spreadsheets/d/1KXQCnJx3ZR7lmobDtwgqCKs-gpL83bYcEiqyRtyNgL0/edit?usp=sharing
A18: O que isso significa? Nada, só quis dar meus parabéns ao trabalho desses caras. Esse nível de consistência com entrega é admirável!
A20: Obs: Tem 2 números repetidos na lista do feed referente a NerdCast, o 205 e o 241. Ambos tem 2 episódios cada associados a esse #, mas publicados em dias diferentes e temas diferentes. Considerando que tem vários ep com A e B, não faz diferença, mas se quiserem contestar qual será o verdadeiro ep 1000, fiquem à vontade
A22: Obs2: Eu ajustei episódios de Empreendedor para NerdCast pois estão listados na sequência dos NCs. Os que ganharam sequência própria ficaram fora dessa lista
